<?xml version="1.0" ?>
<!-- =================================================================================== -->
<!-- |    This document was autogenerated by xacro from alphabot_base.xacro            | -->
<!-- |    EDITING THIS FILE BY HAND IS NOT RECOMMENDED                                 | -->
<!-- =================================================================================== -->
<robot name="alphabot_base">
  <material name="silver">
    <color rgba="0.700 0.700 0.700 1.000"/>
  </material>
  <transmission name="left_joint_tran">
    <type>transmission_interface/SimpleTransmission</type>
    <joint name="left_joint">
      <hardwareInterface>hardware_interface/EffortJointInterface</hardwareInterface>
    </joint>
    <actuator name="left_joint_actr">
      <hardwareInterface>hardware_interface/EffortJointInterface</hardwareInterface>
      <mechanicalReduction>1</mechanicalReduction>
    </actuator>
  </transmission>
  <transmission name="right_joint_tran">
    <type>transmission_interface/SimpleTransmission</type>
    <joint name="right_joint">
      <hardwareInterface>hardware_interface/EffortJointInterface</hardwareInterface>
    </joint>
    <actuator name="right_joint_actr">
      <hardwareInterface>hardware_interface/EffortJointInterface</hardwareInterface>
      <mechanicalReduction>1</mechanicalReduction>
    </actuator>
  </transmission>
  <gazebo>
    <plugin filename="libgazebo_ros_control.so" name="control"/>
  </gazebo>
  <gazebo reference="base_link">
    <material>Gazebo/Silver</material>
    <mu1>0.2</mu1>
    <mu2>0.2</mu2>
    <selfCollide>true</selfCollide>
    <gravity>true</gravity>
  </gazebo>
  <gazebo reference="tyre_left_2">
    <material>Gazebo/Silver</material>
    <mu1>0.2</mu1>
    <mu2>0.2</mu2>
    <selfCollide>true</selfCollide>
  </gazebo>
  <gazebo reference="tyre_right_2">
    <material>Gazebo/Silver</material>
    <mu1>0.2</mu1>
    <mu2>0.2</mu2>
    <selfCollide>true</selfCollide>
  </gazebo>
  <!-- <xacro:include filename="/home/namikxfrost/ros_workspaces/ar_ws/src/Innohacks/alphabot_base_description/gazebo/alphabot_base_plugins.gazebo" /> -->
  <link name="base_link">
    <inertial>
      <origin rpy="0 0 0" xyz="0.10955796271120455 0.00244443549563504 0.04154096131754149"/>
      <mass value="2.0054173190533096"/>
      <inertia ixx="0.002691" ixy="-2.9e-05" ixz="9.6e-05" iyy="0.005622" iyz="1e-06" izz="0.006954"/>
    </inertial>
    <visual>
      <origin rpy="0 0 0" xyz="0 0 0"/>
      <geometry>
        <mesh filename="package://alphabot_base_description/meshes/base_link.stl" scale="0.001 0.001 0.001"/>
      </geometry>
      <material name="silver"/>
    </visual>
    <collision>
      <origin rpy="0 0 0" xyz="0 0 0"/>
      <geometry>
        <mesh filename="package://alphabot_base_description/meshes/base_link.stl" scale="0.001 0.001 0.001"/>
      </geometry>
    </collision>
  </link>
  <link name="tyre_left_2">
    <inertial>
      <origin rpy="0 0 0" xyz="-1.0291917068583345e-08 -0.015890267820055454 5.6733905702544e-07"/>
      <mass value="0.233413023744858"/>
      <inertia ixx="9.6e-05" ixy="-0.0" ixz="0.0" iyy="0.00016" iyz="0.0" izz="9.6e-05"/>
    </inertial>
    <visual>
      <origin rpy="0 0 0" xyz="-0.13535 0.055077 -0.031954"/>
      <geometry>
        <mesh filename="package://alphabot_base_description/meshes/tyre_left_2.stl" scale="0.001 0.001 0.001"/>
      </geometry>
      <material name="silver"/>
    </visual>
    <collision>
      <origin rpy="0 0 0" xyz="-0.13535 0.055077 -0.031954"/>
      <geometry>
        <mesh filename="package://alphabot_base_description/meshes/tyre_left_2.stl" scale="0.001 0.001 0.001"/>
      </geometry>
    </collision>
  </link>
  <link name="tyre_right_2">
    <inertial>
      <origin rpy="0 0 0" xyz="-6.416216058457991e-09 0.015890269546393103 5.80426184441929e-07"/>
      <mass value="0.23341258097957676"/>
      <inertia ixx="9.6e-05" ixy="0.0" ixz="0.0" iyy="0.00016" iyz="-0.0" izz="9.6e-05"/>
    </inertial>
    <visual>
      <origin rpy="0 0 0" xyz="-0.13535 -0.059077 -0.031954"/>
      <geometry>
        <mesh filename="package://alphabot_base_description/meshes/tyre_right_2.stl" scale="0.001 0.001 0.001"/>
      </geometry>
      <material name="silver"/>
    </visual>
    <collision>
      <origin rpy="0 0 0" xyz="-0.13535 -0.059077 -0.031954"/>
      <geometry>
        <mesh filename="package://alphabot_base_description/meshes/tyre_right_2.stl" scale="0.001 0.001 0.001"/>
      </geometry>
    </collision>
  </link>
  <joint name="left_joint" type="continuous">
    <origin rpy="0 0 0" xyz="0.13535 -0.055077 0.031954"/>
    <parent link="base_link"/>
    <child link="tyre_left_2"/>
    <axis xyz="0.0 1.0 -0.0"/>
  </joint>
  <joint name="right_joint" type="continuous">
    <origin rpy="0 0 0" xyz="0.13535 0.059077 0.031954"/>
    <parent link="base_link"/>
    <child link="tyre_right_2"/>
    <axis xyz="0.0 -1.0 -0.0"/>
  </joint>
</robot>

