<?xml version="1.0" ?>
<robot name="alphabot_base" xmlns:xacro="http://www.ros.org/wiki/xacro">

<xacro:include filename="$(find alphabot_base_description)/urdf/materials.xacro" />
<xacro:include filename="$(find alphabot_base_description)/urdf/alphabot_base.trans" />
<xacro:include filename="$(find alphabot_base_description)/urdf/alphabot_base.gazebo" />
<link name="base_link">
  <inertial>
    <origin xyz="0.10955796271120455 0.00244443549563504 0.04154096131754149" rpy="0 0 0"/>
    <mass value="2.0054173190533096"/>
    <inertia ixx="0.002691" iyy="0.005622" izz="0.006954" ixy="-2.9e-05" iyz="1e-06" ixz="9.6e-05"/>
  </inertial>
  <visual>
    <origin xyz="0 0 0" rpy="0 0 0"/>
    <geometry>
      <mesh filename="package://alphabot_base_description/meshes/base_link.stl" scale="0.001 0.001 0.001"/>
    </geometry>
    <material name="silver"/>
  </visual>
  <collision>
    <origin xyz="0 0 0" rpy="0 0 0"/>
    <geometry>
      <mesh filename="package://alphabot_base_description/meshes/base_link.stl" scale="0.001 0.001 0.001"/>
    </geometry>
  </collision>
</link>

<link name="tyre_left_2">
  <inertial>
    <origin xyz="-1.0291917068583345e-08 -0.015890267820055454 5.6733905702544e-07" rpy="0 0 0"/>
    <mass value="0.233413023744858"/>
    <inertia ixx="9.6e-05" iyy="0.00016" izz="9.6e-05" ixy="-0.0" iyz="0.0" ixz="0.0"/>
  </inertial>
  <visual>
    <origin xyz="-0.13535 0.055077 -0.031954" rpy="0 0 0"/>
    <geometry>
      <mesh filename="package://alphabot_base_description/meshes/tyre_left_2.stl" scale="0.001 0.001 0.001"/>
    </geometry>
    <material name="silver"/>
  </visual>
  <collision>
    <origin xyz="-0.13535 0.055077 -0.031954" rpy="0 0 0"/>
    <geometry>
      <mesh filename="package://alphabot_base_description/meshes/tyre_left_2.stl" scale="0.001 0.001 0.001"/>
    </geometry>
  </collision>
</link>

<link name="tyre_right_2">
  <inertial>
    <origin xyz="-6.416216058457991e-09 0.015890269546393103 5.80426184441929e-07" rpy="0 0 0"/>
    <mass value="0.23341258097957676"/>
    <inertia ixx="9.6e-05" iyy="0.00016" izz="9.6e-05" ixy="0.0" iyz="-0.0" ixz="0.0"/>
  </inertial>
  <visual>
    <origin xyz="-0.13535 -0.059077 -0.031954" rpy="0 0 0"/>
    <geometry>
      <mesh filename="package://alphabot_base_description/meshes/tyre_right_2.stl" scale="0.001 0.001 0.001"/>
    </geometry>
    <material name="silver"/>
  </visual>
  <collision>
    <origin xyz="-0.13535 -0.059077 -0.031954" rpy="0 0 0"/>
    <geometry>
      <mesh filename="package://alphabot_base_description/meshes/tyre_right_2.stl" scale="0.001 0.001 0.001"/>
    </geometry>
  </collision>
</link>

<joint name="left_joint" type="continuous">
  <origin xyz="0.13535 -0.055077 0.031954" rpy="0 0 0"/>
  <parent link="base_link"/>
  <child link="tyre_left_2"/>
  <axis xyz="0.0 1.0 -0.0"/>
</joint>

<joint name="right_joint" type="continuous">
  <origin xyz="0.13535 0.059077 0.031954" rpy="0 0 0"/>
  <parent link="base_link"/>
  <child link="tyre_right_2"/>
  <axis xyz="0.0 -1.0 -0.0"/>
</joint>

</robot>
